
The following have been reloaded with a version change:
  1) flexiblas/3.3.1 => flexiblas/3.4.4       6) openmpi/4.1.5 => openmpi/5.0.3
  2) gcc/12.3 => gcc/13.3                     7) pmix/4.2.4 => pmix/5.0.2
  3) gcccore/.12.3 => gcccore/.13.3           8) ucc/1.2.0 => ucc/1.3.0
  4) hwloc/2.9.1 => hwloc/2.10.0              9) ucx/1.14.1 => ucx/1.16.0
  5) libfabric/1.18.0 => libfabric/1.21.0

03/20/2025 11:41:37 - WARNING - __main__ -   device: cuda:0, n_gpu: 1
The new embeddings will be initialized from a multivariate normal distribution that has old embeddings' mean and covariance. As described in this article: https://nlp.stanford.edu/~johnhew/vocab-expansion.html. To disable this, use `mean_resizing=False`
03/20/2025 11:41:41 - INFO - __main__ -   Training/evaluation parameters Namespace(output_dir='./saved_models', model_type='t5', encoder_block_size=512, decoder_block_size=256, beam_size=50, model_name='model.bin', checkpoint_model_name='non_domain_model.bin', model_name_or_path='../codebert-base', config_name='', use_non_pretrained_model=False, tokenizer_name='../codebert-base', code_length=256, do_train=False, do_eval=False, do_test=True, load_model_from_checkpoint=False, evaluate_during_training=False, do_local_explanation=False, reasoning_method=None, train_batch_size=4, eval_batch_size=1, gradient_accumulation_steps=1, learning_rate=5e-05, weight_decay=0.0, adam_epsilon=1e-08, max_grad_norm=1.0, max_steps=-1, warmup_steps=0, seed=42, epochs=1, n_gpu=1, device=device(type='cuda', index=0))
Traceback (most recent call last):
  File "/lustre04/scratch/rinao/VulRepair/M2_CodeBERT_PL-NL/codebert_main.py", line 390, in <module>
    main()
  File "/lustre04/scratch/rinao/VulRepair/M2_CodeBERT_PL-NL/codebert_main.py", line 385, in main
    test_dataset = TextDataset(tokenizer, args, file_type='test')
                   ^^^^^^^^^^^^^^^^^^^^^^^^^^^^^^^^^^^^^^^^^^^^^^
  File "/lustre04/scratch/rinao/VulRepair/M2_CodeBERT_PL-NL/codebert_main.py", line 62, in __init__
    data = datasets.load_dataset("MickyMike/cvefixes_bigvul", split="test")
           ^^^^^^^^^^^^^^^^^^^^^^^^^^^^^^^^^^^^^^^^^^^^^^^^^^^^^^^^^^^^^^^^
  File "/localscratch/rinao.54674013.0/env/lib/python3.11/site-packages/datasets/load.py", line 2061, in load_dataset
    builder_instance = load_dataset_builder(
                       ^^^^^^^^^^^^^^^^^^^^^
  File "/localscratch/rinao.54674013.0/env/lib/python3.11/site-packages/datasets/load.py", line 1781, in load_dataset_builder
    dataset_module = dataset_module_factory(
                     ^^^^^^^^^^^^^^^^^^^^^^^
  File "/localscratch/rinao.54674013.0/env/lib/python3.11/site-packages/datasets/load.py", line 1663, in dataset_module_factory
    raise e1 from None
  File "/localscratch/rinao.54674013.0/env/lib/python3.11/site-packages/datasets/load.py", line 1550, in dataset_module_factory
    raise ConnectionError(f"Couldn't reach '{path}' on the Hub ({e.__class__.__name__})") from e
ConnectionError: Couldn't reach 'MickyMike/cvefixes_bigvul' on the Hub (LocalEntryNotFoundError)
