
The following have been reloaded with a version change:
  1) flexiblas/3.3.1 => flexiblas/3.4.4       6) openmpi/4.1.5 => openmpi/5.0.3
  2) gcc/12.3 => gcc/13.3                     7) pmix/4.2.4 => pmix/5.0.2
  3) gcccore/.12.3 => gcccore/.13.3           8) ucc/1.2.0 => ucc/1.3.0
  4) hwloc/2.9.1 => hwloc/2.10.0              9) ucx/1.14.1 => ucx/1.16.0
  5) libfabric/1.18.0 => libfabric/1.21.0

WARNING: Retrying (Retry(total=4, connect=None, read=None, redirect=None, status=None)) after connection broken by 'NewConnectionError('<pip._vendor.urllib3.connection.HTTPSConnection object at 0x1539b5416710>: Failed to establish a new connection: [Errno 101] Network is unreachable')': /simple/sentencepiece/
WARNING: Retrying (Retry(total=3, connect=None, read=None, redirect=None, status=None)) after connection broken by 'NewConnectionError('<pip._vendor.urllib3.connection.HTTPSConnection object at 0x1539b5416c10>: Failed to establish a new connection: [Errno 101] Network is unreachable')': /simple/sentencepiece/
WARNING: Retrying (Retry(total=2, connect=None, read=None, redirect=None, status=None)) after connection broken by 'NewConnectionError('<pip._vendor.urllib3.connection.HTTPSConnection object at 0x1539b5417b10>: Failed to establish a new connection: [Errno 101] Network is unreachable')': /simple/sentencepiece/
WARNING: Retrying (Retry(total=1, connect=None, read=None, redirect=None, status=None)) after connection broken by 'NewConnectionError('<pip._vendor.urllib3.connection.HTTPSConnection object at 0x1539b5404510>: Failed to establish a new connection: [Errno 101] Network is unreachable')': /simple/sentencepiece/
WARNING: Retrying (Retry(total=0, connect=None, read=None, redirect=None, status=None)) after connection broken by 'NewConnectionError('<pip._vendor.urllib3.connection.HTTPSConnection object at 0x1539b5404f10>: Failed to establish a new connection: [Errno 101] Network is unreachable')': /simple/sentencepiece/
Traceback (most recent call last):
  File "/localscratch/rinao.54554366.0/env/lib/python3.11/site-packages/transformers/utils/hub.py", line 342, in cached_file
    resolved_file = hf_hub_download(
                    ^^^^^^^^^^^^^^^^
  File "/localscratch/rinao.54554366.0/env/lib/python3.11/site-packages/huggingface_hub/utils/_validators.py", line 106, in _inner_fn
    validate_repo_id(arg_value)
  File "/localscratch/rinao.54554366.0/env/lib/python3.11/site-packages/huggingface_hub/utils/_validators.py", line 154, in validate_repo_id
    raise HFValidationError(
huggingface_hub.errors.HFValidationError: Repo id must be in the form 'repo_name' or 'namespace/repo_name': './saved_models/model.bin'. Use `repo_type` argument if needed.

The above exception was the direct cause of the following exception:

Traceback (most recent call last):
  File "/lustre04/scratch/rinao/VulRepair/M10_T5_no_pretrain_word_level/analysis.py", line 116, in <module>
    main()
  File "/lustre04/scratch/rinao/VulRepair/M10_T5_no_pretrain_word_level/analysis.py", line 103, in main
    model = T5ForConditionalGeneration.from_pretrained(model_path).to(device)
            ^^^^^^^^^^^^^^^^^^^^^^^^^^^^^^^^^^^^^^^^^^^^^^^^^^^^^^
  File "/localscratch/rinao.54554366.0/env/lib/python3.11/site-packages/transformers/modeling_utils.py", line 262, in _wrapper
    return func(*args, **kwargs)
           ^^^^^^^^^^^^^^^^^^^^^
  File "/localscratch/rinao.54554366.0/env/lib/python3.11/site-packages/transformers/modeling_utils.py", line 3540, in from_pretrained
    resolved_config_file = cached_file(
                           ^^^^^^^^^^^^
  File "/localscratch/rinao.54554366.0/env/lib/python3.11/site-packages/transformers/utils/hub.py", line 408, in cached_file
    raise EnvironmentError(
OSError: Incorrect path_or_model_id: './saved_models/model.bin'. Please provide either the path to a local folder or the repo_id of a model on the Hub.
