04/05/2025 00:15:53 - WARNING - __main__ -   device: cuda:0, n_gpu: 1
Traceback (most recent call last):
  File "/cvmfs/soft.computecanada.ca/easybuild/software/2023/x86-64-v4/Compiler/gcccore/scipy-stack/2023b/lib/python3.11/site-packages/urllib3/connection.py", line 203, in _new_conn
    sock = connection.create_connection(
           ^^^^^^^^^^^^^^^^^^^^^^^^^^^^^
  File "/cvmfs/soft.computecanada.ca/easybuild/software/2023/x86-64-v4/Compiler/gcccore/scipy-stack/2023b/lib/python3.11/site-packages/urllib3/util/connection.py", line 85, in create_connection
    raise err
  File "/cvmfs/soft.computecanada.ca/easybuild/software/2023/x86-64-v4/Compiler/gcccore/scipy-stack/2023b/lib/python3.11/site-packages/urllib3/util/connection.py", line 73, in create_connection
    sock.connect(sa)
OSError: [Errno 101] Network is unreachable

The above exception was the direct cause of the following exception:

Traceback (most recent call last):
  File "/cvmfs/soft.computecanada.ca/easybuild/software/2023/x86-64-v4/Compiler/gcccore/scipy-stack/2023b/lib/python3.11/site-packages/urllib3/connectionpool.py", line 790, in urlopen
    response = self._make_request(
               ^^^^^^^^^^^^^^^^^^^
  File "/cvmfs/soft.computecanada.ca/easybuild/software/2023/x86-64-v4/Compiler/gcccore/scipy-stack/2023b/lib/python3.11/site-packages/urllib3/connectionpool.py", line 491, in _make_request
    raise new_e
  File "/cvmfs/soft.computecanada.ca/easybuild/software/2023/x86-64-v4/Compiler/gcccore/scipy-stack/2023b/lib/python3.11/site-packages/urllib3/connectionpool.py", line 467, in _make_request
    self._validate_conn(conn)
  File "/cvmfs/soft.computecanada.ca/easybuild/software/2023/x86-64-v4/Compiler/gcccore/scipy-stack/2023b/lib/python3.11/site-packages/urllib3/connectionpool.py", line 1092, in _validate_conn
    conn.connect()
  File "/cvmfs/soft.computecanada.ca/easybuild/software/2023/x86-64-v4/Compiler/gcccore/scipy-stack/2023b/lib/python3.11/site-packages/urllib3/connection.py", line 611, in connect
    self.sock = sock = self._new_conn()
                       ^^^^^^^^^^^^^^^^
  File "/cvmfs/soft.computecanada.ca/easybuild/software/2023/x86-64-v4/Compiler/gcccore/scipy-stack/2023b/lib/python3.11/site-packages/urllib3/connection.py", line 218, in _new_conn
    raise NewConnectionError(
urllib3.exceptions.NewConnectionError: <urllib3.connection.HTTPSConnection object at 0x14a57e89c4d0>: Failed to establish a new connection: [Errno 101] Network is unreachable

The above exception was the direct cause of the following exception:

Traceback (most recent call last):
  File "/localscratch/rinao.54981972.0/env/lib/python3.11/site-packages/requests/adapters.py", line 667, in send
    resp = conn.urlopen(
           ^^^^^^^^^^^^^
  File "/cvmfs/soft.computecanada.ca/easybuild/software/2023/x86-64-v4/Compiler/gcccore/scipy-stack/2023b/lib/python3.11/site-packages/urllib3/connectionpool.py", line 844, in urlopen
    retries = retries.increment(
              ^^^^^^^^^^^^^^^^^^
  File "/cvmfs/soft.computecanada.ca/easybuild/software/2023/x86-64-v4/Compiler/gcccore/scipy-stack/2023b/lib/python3.11/site-packages/urllib3/util/retry.py", line 515, in increment
    raise MaxRetryError(_pool, url, reason) from reason  # type: ignore[arg-type]
    ^^^^^^^^^^^^^^^^^^^^^^^^^^^^^^^^^^^^^^^^^^^^^^^^^^^
urllib3.exceptions.MaxRetryError: HTTPSConnectionPool(host='huggingface.co', port=443): Max retries exceeded with url: /t5-base/resolve/main/config.json (Caused by NewConnectionError('<urllib3.connection.HTTPSConnection object at 0x14a57e89c4d0>: Failed to establish a new connection: [Errno 101] Network is unreachable'))

During handling of the above exception, another exception occurred:

Traceback (most recent call last):
  File "/localscratch/rinao.54981972.0/env/lib/python3.11/site-packages/huggingface_hub/file_download.py", line 1376, in _get_metadata_or_catch_error
    metadata = get_hf_file_metadata(
               ^^^^^^^^^^^^^^^^^^^^^
  File "/localscratch/rinao.54981972.0/env/lib/python3.11/site-packages/huggingface_hub/utils/_validators.py", line 114, in _inner_fn
    return fn(*args, **kwargs)
           ^^^^^^^^^^^^^^^^^^^
  File "/localscratch/rinao.54981972.0/env/lib/python3.11/site-packages/huggingface_hub/file_download.py", line 1296, in get_hf_file_metadata
    r = _request_wrapper(
        ^^^^^^^^^^^^^^^^^
  File "/localscratch/rinao.54981972.0/env/lib/python3.11/site-packages/huggingface_hub/file_download.py", line 280, in _request_wrapper
    response = _request_wrapper(
               ^^^^^^^^^^^^^^^^^
  File "/localscratch/rinao.54981972.0/env/lib/python3.11/site-packages/huggingface_hub/file_download.py", line 303, in _request_wrapper
    response = get_session().request(method=method, url=url, **params)
               ^^^^^^^^^^^^^^^^^^^^^^^^^^^^^^^^^^^^^^^^^^^^^^^^^^^^^^^
  File "/localscratch/rinao.54981972.0/env/lib/python3.11/site-packages/requests/sessions.py", line 589, in request
    resp = self.send(prep, **send_kwargs)
           ^^^^^^^^^^^^^^^^^^^^^^^^^^^^^^
  File "/localscratch/rinao.54981972.0/env/lib/python3.11/site-packages/requests/sessions.py", line 703, in send
    r = adapter.send(request, **kwargs)
        ^^^^^^^^^^^^^^^^^^^^^^^^^^^^^^^
  File "/localscratch/rinao.54981972.0/env/lib/python3.11/site-packages/huggingface_hub/utils/_http.py", line 96, in send
    return super().send(request, *args, **kwargs)
           ^^^^^^^^^^^^^^^^^^^^^^^^^^^^^^^^^^^^^^
  File "/localscratch/rinao.54981972.0/env/lib/python3.11/site-packages/requests/adapters.py", line 700, in send
    raise ConnectionError(e, request=request)
requests.exceptions.ConnectionError: (MaxRetryError("HTTPSConnectionPool(host='huggingface.co', port=443): Max retries exceeded with url: /t5-base/resolve/main/config.json (Caused by NewConnectionError('<urllib3.connection.HTTPSConnection object at 0x14a57e89c4d0>: Failed to establish a new connection: [Errno 101] Network is unreachable'))"), '(Request ID: 2a8e8539-9672-42d6-bd98-9a68b9c09c1d)')

The above exception was the direct cause of the following exception:

Traceback (most recent call last):
  File "/localscratch/rinao.54981972.0/env/lib/python3.11/site-packages/transformers/utils/hub.py", line 424, in cached_files
    hf_hub_download(
  File "/localscratch/rinao.54981972.0/env/lib/python3.11/site-packages/huggingface_hub/utils/_validators.py", line 114, in _inner_fn
    return fn(*args, **kwargs)
           ^^^^^^^^^^^^^^^^^^^
  File "/localscratch/rinao.54981972.0/env/lib/python3.11/site-packages/huggingface_hub/file_download.py", line 862, in hf_hub_download
    return _hf_hub_download_to_cache_dir(
           ^^^^^^^^^^^^^^^^^^^^^^^^^^^^^^
  File "/localscratch/rinao.54981972.0/env/lib/python3.11/site-packages/huggingface_hub/file_download.py", line 969, in _hf_hub_download_to_cache_dir
    _raise_on_head_call_error(head_call_error, force_download, local_files_only)
  File "/localscratch/rinao.54981972.0/env/lib/python3.11/site-packages/huggingface_hub/file_download.py", line 1489, in _raise_on_head_call_error
    raise LocalEntryNotFoundError(
huggingface_hub.errors.LocalEntryNotFoundError: An error happened while trying to locate the file on the Hub and we cannot find the requested files in the local cache. Please check your connection and try again or make sure your Internet connection is on.

The above exception was the direct cause of the following exception:

Traceback (most recent call last):
  File "/lustre04/scratch/rinao/VulRepair/M3_T5_no_pretrain_subword/t5_no_pretraining_main.py", line 398, in <module>
    main()
  File "/lustre04/scratch/rinao/VulRepair/M3_T5_no_pretrain_subword/t5_no_pretraining_main.py", line 364, in main
    config = T5Config.from_pretrained(args.config_name)
             ^^^^^^^^^^^^^^^^^^^^^^^^^^^^^^^^^^^^^^^^^^
  File "/localscratch/rinao.54981972.0/env/lib/python3.11/site-packages/transformers/configuration_utils.py", line 554, in from_pretrained
    config_dict, kwargs = cls.get_config_dict(pretrained_model_name_or_path, **kwargs)
                          ^^^^^^^^^^^^^^^^^^^^^^^^^^^^^^^^^^^^^^^^^^^^^^^^^^^^^^^^^^^^
  File "/localscratch/rinao.54981972.0/env/lib/python3.11/site-packages/transformers/configuration_utils.py", line 594, in get_config_dict
    config_dict, kwargs = cls._get_config_dict(pretrained_model_name_or_path, **kwargs)
                          ^^^^^^^^^^^^^^^^^^^^^^^^^^^^^^^^^^^^^^^^^^^^^^^^^^^^^^^^^^^^^
  File "/localscratch/rinao.54981972.0/env/lib/python3.11/site-packages/transformers/configuration_utils.py", line 653, in _get_config_dict
    resolved_config_file = cached_file(
                           ^^^^^^^^^^^^
  File "/localscratch/rinao.54981972.0/env/lib/python3.11/site-packages/transformers/utils/hub.py", line 266, in cached_file
    file = cached_files(path_or_repo_id=path_or_repo_id, filenames=[filename], **kwargs)
           ^^^^^^^^^^^^^^^^^^^^^^^^^^^^^^^^^^^^^^^^^^^^^^^^^^^^^^^^^^^^^^^^^^^^^^^^^^^^^
  File "/localscratch/rinao.54981972.0/env/lib/python3.11/site-packages/transformers/utils/hub.py", line 491, in cached_files
    raise EnvironmentError(
OSError: We couldn't connect to 'https://huggingface.co' to load the files, and couldn't find them in the cached files.
Checkout your internet connection or see how to run the library in offline mode at 'https://huggingface.co/docs/transformers/installation#offline-mode'.
